2022-03-21 21:22:38,081 ERROR: Exception on / [GET] [in /Library/Frameworks/Python.framework/Versions/3.9/lib/python3.9/site-packages/flask/app.py:1457]
Traceback (most recent call last):
  File "/Library/Frameworks/Python.framework/Versions/3.9/lib/python3.9/site-packages/flask/app.py", line 2073, in wsgi_app
    response = self.full_dispatch_request()
  File "/Library/Frameworks/Python.framework/Versions/3.9/lib/python3.9/site-packages/flask/app.py", line 1518, in full_dispatch_request
    rv = self.handle_user_exception(e)
  File "/Library/Frameworks/Python.framework/Versions/3.9/lib/python3.9/site-packages/flask/app.py", line 1516, in full_dispatch_request
    rv = self.dispatch_request()
  File "/Library/Frameworks/Python.framework/Versions/3.9/lib/python3.9/site-packages/flask/app.py", line 1502, in dispatch_request
    return self.ensure_sync(self.view_functions[rule.endpoint])(**req.view_args)
  File "/Users/mcfatem/GitHub/OHScribe/ohscribe.py", line 166, in main
    return render_template('main.html', title='Controls'), #form=form)
  File "/Library/Frameworks/Python.framework/Versions/3.9/lib/python3.9/site-packages/flask/templating.py", line 147, in render_template
    return _render(
  File "/Library/Frameworks/Python.framework/Versions/3.9/lib/python3.9/site-packages/flask/templating.py", line 128, in _render
    rv = template.render(context)
  File "/Library/Frameworks/Python.framework/Versions/3.9/lib/python3.9/site-packages/jinja2/environment.py", line 1291, in render
    self.environment.handle_exception()
  File "/Library/Frameworks/Python.framework/Versions/3.9/lib/python3.9/site-packages/jinja2/environment.py", line 925, in handle_exception
    raise rewrite_traceback_stack(source=source)
  File "/Users/mcfatem/GitHub/OHScribe/templates/main.html", line 3, in top-level template code
    {% extends "base.html" %}
  File "/Users/mcfatem/GitHub/OHScribe/templates/base.html", line 22, in top-level template code
    {% block content %}
  File "/Users/mcfatem/GitHub/OHScribe/templates/base.html", line 35, in block 'content'
    {% block app_content %}{% endblock %}
  File "/Users/mcfatem/GitHub/OHScribe/templates/main.html", line 7, in block 'app_content'
    <form action="{{ url_for('results') }}" method="POST">
  File "/Library/Frameworks/Python.framework/Versions/3.9/lib/python3.9/site-packages/flask/helpers.py", line 338, in url_for
    return appctx.app.handle_url_build_error(error, endpoint, values)
  File "/Library/Frameworks/Python.framework/Versions/3.9/lib/python3.9/site-packages/flask/helpers.py", line 325, in url_for
    rv = url_adapter.build(
  File "/Library/Frameworks/Python.framework/Versions/3.9/lib/python3.9/site-packages/werkzeug/routing.py", line 2315, in build
    raise BuildError(endpoint, values, method, self)
werkzeug.routing.BuildError: Could not build url for endpoint 'results'. Did you mean 'static' instead?
2022-03-21 21:22:38,929 ERROR: Exception on / [GET] [in /Library/Frameworks/Python.framework/Versions/3.9/lib/python3.9/site-packages/flask/app.py:1457]
Traceback (most recent call last):
  File "/Library/Frameworks/Python.framework/Versions/3.9/lib/python3.9/site-packages/flask/app.py", line 2073, in wsgi_app
    response = self.full_dispatch_request()
  File "/Library/Frameworks/Python.framework/Versions/3.9/lib/python3.9/site-packages/flask/app.py", line 1518, in full_dispatch_request
    rv = self.handle_user_exception(e)
  File "/Library/Frameworks/Python.framework/Versions/3.9/lib/python3.9/site-packages/flask/app.py", line 1516, in full_dispatch_request
    rv = self.dispatch_request()
  File "/Library/Frameworks/Python.framework/Versions/3.9/lib/python3.9/site-packages/flask/app.py", line 1502, in dispatch_request
    return self.ensure_sync(self.view_functions[rule.endpoint])(**req.view_args)
  File "/Users/mcfatem/GitHub/OHScribe/ohscribe.py", line 166, in main
    return render_template('main.html', title='Controls'), #form=form)
  File "/Library/Frameworks/Python.framework/Versions/3.9/lib/python3.9/site-packages/flask/templating.py", line 147, in render_template
    return _render(
  File "/Library/Frameworks/Python.framework/Versions/3.9/lib/python3.9/site-packages/flask/templating.py", line 128, in _render
    rv = template.render(context)
  File "/Library/Frameworks/Python.framework/Versions/3.9/lib/python3.9/site-packages/jinja2/environment.py", line 1291, in render
    self.environment.handle_exception()
  File "/Library/Frameworks/Python.framework/Versions/3.9/lib/python3.9/site-packages/jinja2/environment.py", line 925, in handle_exception
    raise rewrite_traceback_stack(source=source)
  File "/Users/mcfatem/GitHub/OHScribe/templates/main.html", line 3, in top-level template code
    {% extends "base.html" %}
  File "/Users/mcfatem/GitHub/OHScribe/templates/base.html", line 22, in top-level template code
    {% block content %}
  File "/Users/mcfatem/GitHub/OHScribe/templates/base.html", line 35, in block 'content'
    {% block app_content %}{% endblock %}
  File "/Users/mcfatem/GitHub/OHScribe/templates/main.html", line 7, in block 'app_content'
    <form action="{{ url_for('results') }}" method="POST">
  File "/Library/Frameworks/Python.framework/Versions/3.9/lib/python3.9/site-packages/flask/helpers.py", line 338, in url_for
    return appctx.app.handle_url_build_error(error, endpoint, values)
  File "/Library/Frameworks/Python.framework/Versions/3.9/lib/python3.9/site-packages/flask/helpers.py", line 325, in url_for
    rv = url_adapter.build(
  File "/Library/Frameworks/Python.framework/Versions/3.9/lib/python3.9/site-packages/werkzeug/routing.py", line 2315, in build
    raise BuildError(endpoint, values, method, self)
werkzeug.routing.BuildError: Could not build url for endpoint 'results'. Did you mean 'static' instead?
2022-03-21 21:22:40,697 DEBUG: upload_file( ) called [in /Users/mcfatem/GitHub/OHScribe/ohscribe.py:102]
2022-03-21 21:24:47,435 INFO: OHScribe startup with LOG_VERBOSITY = DEBUG. [in /Users/mcfatem/GitHub/OHScribe/ohscribe.py:47]
2022-03-21 21:24:49,275 ERROR: Exception on / [GET] [in /Library/Frameworks/Python.framework/Versions/3.9/lib/python3.9/site-packages/flask/app.py:1457]
Traceback (most recent call last):
  File "/Library/Frameworks/Python.framework/Versions/3.9/lib/python3.9/site-packages/flask/app.py", line 2073, in wsgi_app
    response = self.full_dispatch_request()
  File "/Library/Frameworks/Python.framework/Versions/3.9/lib/python3.9/site-packages/flask/app.py", line 1518, in full_dispatch_request
    rv = self.handle_user_exception(e)
  File "/Library/Frameworks/Python.framework/Versions/3.9/lib/python3.9/site-packages/flask/app.py", line 1516, in full_dispatch_request
    rv = self.dispatch_request()
  File "/Library/Frameworks/Python.framework/Versions/3.9/lib/python3.9/site-packages/flask/app.py", line 1502, in dispatch_request
    return self.ensure_sync(self.view_functions[rule.endpoint])(**req.view_args)
  File "/Users/mcfatem/GitHub/OHScribe/ohscribe.py", line 163, in main
    form = MainForm(request.form)
NameError: name 'MainForm' is not defined
2022-03-21 21:24:55,273 ERROR: Exception on / [GET] [in /Library/Frameworks/Python.framework/Versions/3.9/lib/python3.9/site-packages/flask/app.py:1457]
Traceback (most recent call last):
  File "/Library/Frameworks/Python.framework/Versions/3.9/lib/python3.9/site-packages/flask/app.py", line 2073, in wsgi_app
    response = self.full_dispatch_request()
  File "/Library/Frameworks/Python.framework/Versions/3.9/lib/python3.9/site-packages/flask/app.py", line 1518, in full_dispatch_request
    rv = self.handle_user_exception(e)
  File "/Library/Frameworks/Python.framework/Versions/3.9/lib/python3.9/site-packages/flask/app.py", line 1516, in full_dispatch_request
    rv = self.dispatch_request()
  File "/Library/Frameworks/Python.framework/Versions/3.9/lib/python3.9/site-packages/flask/app.py", line 1502, in dispatch_request
    return self.ensure_sync(self.view_functions[rule.endpoint])(**req.view_args)
  File "/Users/mcfatem/GitHub/OHScribe/ohscribe.py", line 163, in main
    form = MainForm(request.form)
NameError: name 'MainForm' is not defined
2022-03-21 21:24:56,902 ERROR: Exception on / [GET] [in /Library/Frameworks/Python.framework/Versions/3.9/lib/python3.9/site-packages/flask/app.py:1457]
Traceback (most recent call last):
  File "/Library/Frameworks/Python.framework/Versions/3.9/lib/python3.9/site-packages/flask/app.py", line 2073, in wsgi_app
    response = self.full_dispatch_request()
  File "/Library/Frameworks/Python.framework/Versions/3.9/lib/python3.9/site-packages/flask/app.py", line 1518, in full_dispatch_request
    rv = self.handle_user_exception(e)
  File "/Library/Frameworks/Python.framework/Versions/3.9/lib/python3.9/site-packages/flask/app.py", line 1516, in full_dispatch_request
    rv = self.dispatch_request()
  File "/Library/Frameworks/Python.framework/Versions/3.9/lib/python3.9/site-packages/flask/app.py", line 1502, in dispatch_request
    return self.ensure_sync(self.view_functions[rule.endpoint])(**req.view_args)
  File "/Users/mcfatem/GitHub/OHScribe/ohscribe.py", line 163, in main
    form = MainForm(request.form)
NameError: name 'MainForm' is not defined
2022-03-21 21:24:57,836 DEBUG: upload_file( ) called [in /Users/mcfatem/GitHub/OHScribe/ohscribe.py:102]
